2024-11-05 14:19:06,230 ERROR: Exception on /users/all [GET]
Traceback (most recent call last):
  File "D:\Code\Python\Lib\site-packages\flask\app.py", line 1473, in wsgi_app
    response = self.full_dispatch_request()
               ^^^^^^^^^^^^^^^^^^^^^^^^^^^^
  File "D:\Code\Python\Lib\site-packages\flask\app.py", line 882, in full_dispatch_request
    rv = self.handle_user_exception(e)
         ^^^^^^^^^^^^^^^^^^^^^^^^^^^^^
  File "D:\Code\Python\Lib\site-packages\flask\app.py", line 880, in full_dispatch_request
    rv = self.dispatch_request()
         ^^^^^^^^^^^^^^^^^^^^^^^
  File "D:\Code\Python\Lib\site-packages\flask\app.py", line 865, in dispatch_request
    return self.ensure_sync(self.view_functions[rule.endpoint])(**view_args)  # type: ignore[no-any-return]
           ^^^^^^^^^^^^^^^^^^^^^^^^^^^^^^^^^^^^^^^^^^^^^^^^^^^^^^^^^^^^^^^^^
  File "D:\Code\ADM_HR_STO_V3\app\routes.py", line 20, in decorated
    data = jwt.decode(token, app.config['SECRET_KEY'], algorithms=['HS256'])
                             ^^^
NameError: name 'app' is not defined
2024-11-05 14:26:53,946 ERROR: Exception on /users/all [GET]
Traceback (most recent call last):
  File "D:\Code\Python\Lib\site-packages\flask\app.py", line 1473, in wsgi_app
    response = self.full_dispatch_request()
               ^^^^^^^^^^^^^^^^^^^^^^^^^^^^
  File "D:\Code\Python\Lib\site-packages\flask\app.py", line 882, in full_dispatch_request
    rv = self.handle_user_exception(e)
         ^^^^^^^^^^^^^^^^^^^^^^^^^^^^^
  File "D:\Code\Python\Lib\site-packages\flask\app.py", line 880, in full_dispatch_request
    rv = self.dispatch_request()
         ^^^^^^^^^^^^^^^^^^^^^^^
  File "D:\Code\Python\Lib\site-packages\flask\app.py", line 865, in dispatch_request
    return self.ensure_sync(self.view_functions[rule.endpoint])(**view_args)  # type: ignore[no-any-return]
           ^^^^^^^^^^^^^^^^^^^^^^^^^^^^^^^^^^^^^^^^^^^^^^^^^^^^^^^^^^^^^^^^^
  File "D:\Code\ADM_HR_STO_V3\app\routes.py", line 20, in decorated
    data = jwt.decode(token, app.config['SECRET_KEY'], algorithms=['HS256'])
                             ^^^
NameError: name 'app' is not defined
2024-11-05 14:28:47,978 ERROR: Exception on /users/all [GET]
Traceback (most recent call last):
  File "D:\Code\Python\Lib\site-packages\flask\app.py", line 1473, in wsgi_app
    response = self.full_dispatch_request()
               ^^^^^^^^^^^^^^^^^^^^^^^^^^^^
  File "D:\Code\Python\Lib\site-packages\flask\app.py", line 882, in full_dispatch_request
    rv = self.handle_user_exception(e)
         ^^^^^^^^^^^^^^^^^^^^^^^^^^^^^
  File "D:\Code\Python\Lib\site-packages\flask\app.py", line 880, in full_dispatch_request
    rv = self.dispatch_request()
         ^^^^^^^^^^^^^^^^^^^^^^^
  File "D:\Code\Python\Lib\site-packages\flask\app.py", line 865, in dispatch_request
    return self.ensure_sync(self.view_functions[rule.endpoint])(**view_args)  # type: ignore[no-any-return]
           ^^^^^^^^^^^^^^^^^^^^^^^^^^^^^^^^^^^^^^^^^^^^^^^^^^^^^^^^^^^^^^^^^
  File "D:\Code\ADM_HR_STO_V3\app\routes.py", line 20, in decorated
    data = jwt.decode(token, app.config['SECRET_KEY'], algorithms=['HS256'])
                             ^^^
NameError: name 'app' is not defined
2024-11-05 15:03:20,644 ERROR: Error in /users: too many values to unpack (expected 4)
Traceback (most recent call last):
  File "D:\Code\ADM_HR_STO_V3\app\routes.py", line 123, in get_users
    npk, name, email, jabatan = row
    ^^^^^^^^^^^^^^^^^^^^^^^^^
ValueError: too many values to unpack (expected 4)
2024-11-05 15:04:08,417 ERROR: Error in /users: too many values to unpack (expected 4)
Traceback (most recent call last):
  File "D:\Code\ADM_HR_STO_V3\app\routes.py", line 123, in get_users
    npk, name, email, jabatan = row
    ^^^^^^^^^^^^^^^^^^^^^^^^^
ValueError: too many values to unpack (expected 4)
2024-11-05 15:05:56,812 ERROR: Error in /users: ('42000', "[42000] [Microsoft][ODBC Driver 17 for SQL Server][SQL Server]Incorrect syntax near the keyword 'where'. (156) (SQLExecDirectW)")
Traceback (most recent call last):
  File "D:\Code\ADM_HR_STO_V3\app\routes.py", line 118, in get_users
    cursor.execute("SELECT npk, name, email, jabatan,dir,div,dept FROM HRIS_TrAD ORDER BY npk where email like '%@daihatsu%'")
pyodbc.ProgrammingError: ('42000', "[42000] [Microsoft][ODBC Driver 17 for SQL Server][SQL Server]Incorrect syntax near the keyword 'where'. (156) (SQLExecDirectW)")
